<?xml version="1.0" encoding="utf-8"?>
<robot name="morphing_lander">
<!-- links -->
  <link name="base_link">
    <inertial>
      <origin
        xyz="-0.012442 -0.00049816 0.081712"
        rpy="0 0 0" />
      <mass
        value="1.3975" />
      <inertia
        ixx="0.0027307"
        ixy="-4.8622E-07"
        ixz="0.00020344"
        iyy="0.0077626"
        iyz="1.1505E-07"
        izz="0.0068798" />
    </inertial>
    <visual>
      <origin
        xyz="0 0 0"
        rpy="0 0 0" />
      <geometry>
        <mesh
          filename="package://m4/meshes/base_link.STL" />
      </geometry>
      <material
        name="">
        <color
          rgba="0.75294 0.75294 0.75294 1" />
      </material>
    </visual>
    <collision>
      <origin
        xyz="0 0 0"
        rpy="0 0 0" />
      <geometry>
        <mesh
          filename="package://m4/meshes/base_link.STL" />
      </geometry>
    </collision>
  </link>
  <link name="l0">
    <inertial>
      <origin
        xyz="-0.00010221 1.3428E-08 7.3683E-05"
        rpy="0 0 0" />
      <mass
        value="0.0047277" />
      <inertia
        ixx="7.3274E-07"
        ixy="-3.6769E-13"
        ixz="-3.1502E-09"
        iyy="1.7742E-07"
        iyz="2.8255E-13"
        izz="7.8608E-07" />
    </inertial>
    <visual>
      <origin
        xyz="0 0 0"
        rpy="0 0 0" />
      <geometry>
        <mesh
          filename="package://m4/meshes/l0.STL" />
      </geometry>
      <material
        name="">
        <color
          rgba="0.79216 0.81961 0.93333 1" />
      </material>
    </visual>
    <collision>
      <origin
        xyz="0 0 0"
        rpy="0 0 0" />
      <geometry>
        <mesh
          filename="package://m4/meshes/l0.STL" />
      </geometry>
    </collision>
  </link>
  <link name="arml">
    <inertial>
      <origin
        xyz="0.00019959 0.12728 0.028398"
        rpy="0 0 0" />
      <mass
        value="0.92861" />
      <inertia
        ixx="0.0040822"
        ixy="-2.9088E-07"
        ixz="1.6918E-08"
        iyy="0.0048141"
        iyz="4.3647E-09"
        izz="0.0087629" />
    </inertial>
    <visual>
      <origin
        xyz="0 0 0"
        rpy="0 0 0" />
      <geometry>
        <mesh
          filename="package://m4/meshes/arml.STL" />
      </geometry>
      <material
        name="">
        <color
          rgba="0.75294 0.75294 0.75294 1" />
      </material>
    </visual>
    <collision>
      <origin
        xyz="0 0 0"
        rpy="0 0 0" />
      <geometry>
        <mesh
          filename="package://m4/meshes/arml.STL" />
      </geometry>
    </collision>
  </link>
  <link name="armr">
    <inertial>
      <origin
        xyz="0 0 0"
        rpy="0 0 0" />
      <mass
        value="0.92861" />
      <inertia
        ixx="0.0040822"
        ixy="-2.9088E-07"
        ixz="-1.6918E-08"
        iyy="0.0048141"
        iyz="-4.3647E-09"
        izz="0.0087629" />
    </inertial>
    <visual>
      <origin
        xyz="0 0 0"
        rpy="0 0 0" />
      <geometry>
        <mesh
          filename="package://m4/meshes/armr.STL" />
      </geometry>
      <material
        name="">
        <color
          rgba="1 1 1 1" />
      </material>
    </visual>
    <collision>
      <origin
        xyz="0 0 0"
        rpy="0 0 0" />
      <geometry>
        <mesh
          filename="package://m4/meshes/armr.STL" />
      </geometry>
    </collision>
  </link>
  <link name="rotor0">
    <inertial>
      <origin
        xyz="8.709E-06 4.3361E-06 0.0061124"
        rpy="0 0 0" />
      <mass
        value="0.0071415" />
      <inertia
        ixx="7.3155E-06"
        ixy="1.4991E-09"
        ixz="-3.786E-10"
        iyy="7.3155E-06"
        iyz="2.4588E-12"
        izz="1.4546E-05" />
    </inertial>
    <visual>
      <origin
        xyz="0 0 0"
        rpy="0 0 0" />
      <geometry>
        <mesh
          filename="package://m4/meshes/rotor0.STL" />
      </geometry>
      <material
        name="">
        <color
          rgba="0.50196 0.50196 0.50196 1" />
      </material>
    </visual>
    <collision>
      <origin
        xyz="0 0 0"
        rpy="0 0 0" />
      <geometry>
        <mesh
          filename="package://m4/meshes/rotor0.STL" />
      </geometry>
    </collision>
  </link>
  <link name="rotor1">
    <inertial>
      <origin
        xyz="-8.8003E-06 -4.4578E-06 0.0061124"
        rpy="0 0 0" />
      <mass
        value="0.0071414" />
      <inertia
        ixx="7.3156E-06"
        ixy="1.5289E-09"
        ixz="3.7763E-10"
        iyy="7.3155E-06"
        iyz="-3.6884E-12"
        izz="1.4546E-05" />
    </inertial>
    <visual>
      <origin
        xyz="0 0 0"
        rpy="0 0 0" />
      <geometry>
        <mesh
          filename="package://m4/meshes/rotor1.STL" />
      </geometry>
      <material
        name="">
        <color
          rgba="0.50196 0.50196 0.50196 1" />
      </material>
    </visual>
    <collision>
      <origin
        xyz="0 0 0"
        rpy="0 0 0" />
      <geometry>
        <mesh
          filename="package://m4/meshes/rotor1.STL" />
      </geometry>
    </collision>
  </link>
  <link name="rotor2">
    <inertial>
      <origin
        xyz="-1.5704E-05 8.0308E-06 0.0061096"
        rpy="0 0 0" />
      <mass
        value="0.0071457" />
      <inertia
        ixx="7.3203E-06"
        ixy="-1.3287E-09"
        ixz="-2.4103E-10"
        iyy="7.3144E-06"
        iyz="1.672E-10"
        izz="1.455E-05" />
    </inertial>
    <visual>
      <origin
        xyz="0 0 0"
        rpy="0 0 0" />
      <geometry>
        <mesh
          filename="package://m4/meshes/rotor2.STL" />
      </geometry>
      <material
        name="">
        <color
          rgba="0.75294 0.75294 0.75294 1" />
      </material>
    </visual>
    <collision>
      <origin
        xyz="0 0 0"
        rpy="0 0 0" />
      <geometry>
        <mesh
          filename="package://m4/meshes/rotor2.STL" />
      </geometry>
    </collision>
  </link>
  <link name="rotor3">
    <inertial>
      <origin
        xyz="1.5942E-05 -7.8741E-06 0.0061096"
        rpy="0 0 0" />
      <mass
        value="0.0071457" />
      <inertia
        ixx="7.3203E-06"
        ixy="-1.4137E-09"
        ixz="2.4357E-10"
        iyy="7.3145E-06"
        iyz="-1.6554E-10"
        izz="1.455E-05" />
    </inertial>
    <visual>
      <origin
        xyz="0 0 0"
        rpy="0 0 0" />
      <geometry>
        <mesh
          filename="package://m4/meshes/rotor3.STL" />
      </geometry>
      <material
        name="">
        <color
          rgba="0.75294 0.75294 0.75294 1" />
      </material>
    </visual>
    <collision>
      <origin
        xyz="0 0 0"
        rpy="0 0 0" />
      <geometry>
        <mesh
          filename="package://m4/meshes/rotor3.STL" />
      </geometry>
    </collision>
  </link>
<!-- joints -->
  <joint name="base_to_arml"
    type="revolute">
    <origin
      xyz="0 0.068 0.094"
      rpy="0 0 0" />
    <parent
      link="base_link" />
    <child
      link="arml" />
    <axis
      xyz="1 0 0" />
    <limit
      lower="-1.5"
      upper="1.5"
      effort="0"
      velocity="0" />
  </joint>
  <joint name="base_to_armr"
    type="revolute">
    <origin
      xyz="0 -0.068 0.094"
      rpy="0 0 0" />
    <parent
      link="base_link" />
    <child
      link="armr" />
    <axis
      xyz="-1 0 0" />
    <limit
      lower="-1.5"
      upper="1.5"
      effort="0"
      velocity="0" />
  </joint>
  <joint name="armr_to_rotor0"
    type="revolute">
    <origin
      xyz="0.165000000000003 -0.136729999999994 0.0625625000000005"
      rpy="0 0 0" />
    <parent
      link="armr" />
    <child
      link="rotor0" />
    <axis
      xyz="0 0 1" />
    <limit
      lower="-1000000000000"
      upper="1000000000000"
      effort="0"
      velocity="0" />
  </joint>
  <joint name="arml_to_rotor1"
    type="revolute">
    <origin
      xyz="-0.165000000000003 0.136729999999994 0.062562499999999"
      rpy="0 0 0" />
    <parent
      link="arml" />
    <child
      link="rotor1" />
    <axis
      xyz="0 0 1" />
    <limit
      lower="-1000000000000"
      upper="1000000000000"
      effort="0"
      velocity="0" />
  </joint>
  <joint name="arml_to_rotor2"
    type="revolute">
    <origin
      xyz="0.165 0.136730000000001 0.062562499999999"
      rpy="0 0 0" />
    <parent
      link="arml" />
    <child
      link="rotor2" />
    <axis
      xyz="0 0 1" />
    <limit
      lower="-1000000000000"
      upper="1000000000000"
      effort="0"
      velocity="0" />
  </joint>
  <joint name="armr_to_rotor3"
    type="revolute">
    <origin
      xyz="-0.165 -0.13673 0.0625625000000006"
      rpy="0 0 0" />
    <parent
      link="armr" />
    <child
      link="rotor3" />
    <axis
      xyz="0 0 1" />
    <limit
      lower="-1000000000000"
      upper="1000000000000"
      effort="0"
      velocity="0" />
  </joint>

</robot>


  <link name="l1lcopy">
    <inertial>
      <origin
        xyz="8.6736E-18 -0.0029929 -0.025752"
        rpy="0 0 0" />
      <mass
        value="0.008134" />
      <inertia
        ixx="2.0029E-06"
        ixy="2.0777E-22"
        ixz="4.56E-22"
        iyy="2.5773E-06"
        iyz="-2.1355E-07"
        izz="7.6459E-07" />
    </inertial>
    <visual>
      <origin
        xyz="0 0 0"
        rpy="0 0 0" />
      <geometry>
        <mesh
          filename="package://m4/meshes/l1lcopy.STL" />
      </geometry>
      <material
        name="">
        <color
          rgba="0.79216 0.81961 0.93333 1" />
      </material>
    </visual>
    <collision>
      <origin
        xyz="0 0 0"
        rpy="0 0 0" />
      <geometry>
        <mesh
          filename="package://m4/meshes/l1lcopy.STL" />
      </geometry>
    </collision>
  </link>
  <link name="l1rcopy">
    <inertial>
      <origin
        xyz="-9.541E-17 0.0029929 -0.025752"
        rpy="0 0 0" />
      <mass
        value="0.008134" />
      <inertia
        ixx="2.0029E-06"
        ixy="-2.6367E-22"
        ixz="-8.7912E-22"
        iyy="2.5773E-06"
        iyz="2.1355E-07"
        izz="7.6459E-07" />
    </inertial>
    <visual>
      <origin
        xyz="0 0 0"
        rpy="0 0 0" />
      <geometry>
        <mesh
          filename="package://m4/meshes/l1rcopy.STL" />
      </geometry>
      <material
        name="">
        <color
          rgba="0.79216 0.81961 0.93333 1" />
      </material>
    </visual>
    <collision>
      <origin
        xyz="0 0 0"
        rpy="0 0 0" />
      <geometry>
        <mesh
          filename="package://m4/meshes/l1rcopy.STL" />
      </geometry>
    </collision>
  </link>
  <joint name="arml_to_l1lcopy"
    type="revolute">
    <origin
      xyz="0 -0.046 0"
      rpy="0 0 0" />
    <parent
      link="arml" />
    <child
      link="l1lcopy" />
    <axis
      xyz="1 0 0" />
    <limit
      lower="-10"
      upper="10"
      effort="0"
      velocity="0" />
  </joint>
  <joint name="armr_to_l1rcopy"
    type="revolute">
    <origin
      xyz="0 0.046 0"
      rpy="0 0 0" />
    <parent
      link="armr" />
    <child
      link="l1rcopy" />
    <axis
      xyz="-1 0 0" />
    <limit
      lower="-10"
      upper="10"
      effort="0"
      velocity="0" />
  </joint>
