<sdf version='1.7'>
  <model name='m4'>
  <!-- <enable_lockstep>false</enable_lockstep> -->
<!-- links -->
    <link name='base_link'>
      <inertial>
        <pose>-0.0067 0.00048 0.073 0 0 0</pose>
        <mass>2.33</mass>
        <inertia>
          <ixx>0.0067</ixx>
          <ixy>-3.1E-05</ixy>
          <ixz>0.00046</ixz>
          <iyy>0.011</iyy>
          <iyz>4E-05</iyz>
          <izz>0.0088</izz>
        </inertia>
      </inertial>
      <collision name='base_link_collision'>
        <pose>0 0 0 0 0 0</pose>
        <geometry>
          <mesh>
            <scale>1 1 1</scale>
            <uri>model://m4/meshes/base_link.STL</uri>
          </mesh>
        </geometry>
      </collision>
      <visual name='base_link_visual'>
        <pose>0 0 0 0 -0 0</pose>
        <geometry>
          <mesh>
            <scale>1 1 1</scale>
            <uri>model://m4/meshes/base_link.STL</uri>
          </mesh>
        </geometry>
      </visual>
    </link>
    <link name='arml'>
      <pose relative_to='base_to_arml'>0 0 0 0 -0 0</pose>
      <inertial>
        <pose>0.00032 0.16739 0.02495 0 -0 0</pose>
        <mass>1.537</mass>
        <inertia>
          <ixx>0.008732</ixx>
          <ixy>7E-06</ixy>
          <ixz>-1.2E-05</ixz>
          <iyy>0.036926</iyy>
          <iyz>0.000571</iyz>
          <izz>0.04382</izz>
        </inertia>
      </inertial>
      <visual name='arml_visual'>
        <pose>0 0 0 0 -0 0</pose>
        <geometry>
          <mesh>
            <scale>1 1 1</scale>
            <uri>model://m4/meshes/arml.STL</uri>
          </mesh>
        </geometry>
      </visual>
      <collision name='arml_collision'>
        <pose>0 0 0 0 0 0</pose>
        <geometry>
          <mesh>
            <scale>1 1 1</scale>
            <uri>model://m4/meshes/arml.STL</uri>
          </mesh>
        </geometry>
      </collision>
    </link>
    <link name='armr'>
      <pose relative_to='base_to_armr'>0 0 0 0 -0 0</pose>
      <inertial>
        <pose>-0.00032 -0.16739 0.02495 0 0 0</pose>
        <mass>1.537</mass>
        <inertia>
          <ixx>0.008732</ixx>
          <ixy>7E-06</ixy>
          <ixz>1.2E-05</ixz>
          <iyy>0.036926</iyy>
          <iyz>-0.000571</iyz>
          <izz>0.04382</izz>
        </inertia>
      </inertial>
      <visual name='armr_visual'>
        <pose>0 0 0 0 -0 0</pose>
        <geometry>
          <mesh>
            <scale>1 1 1</scale>
            <uri>model://m4/meshes/armr.STL</uri>
          </mesh>
        </geometry>
      </visual>
      <collision name='armr_collision'>
        <pose>0 0 0 0 0 0</pose>
        <geometry>
          <mesh>
            <scale>1 1 1</scale>
            <uri>model://m4/meshes/armr.STL</uri>
          </mesh>
        </geometry>
      </collision>
    </link>
    <link name='rotor0'>
      <!-- <kinematic>true</kinematic> -->
      <pose relative_to='armr_to_rotor0'>0 0 0 0 -0 0</pose>
      <inertial>
        <pose>0 0 0 0 0 0</pose>
        <mass>0.021</mass>
        <inertia>
          <ixx>2.2E-05</ixx>
          <ixy>0</ixy>
          <ixz>0</ixz>
          <iyy>2.2E-05</iyy>
          <iyz>0</iyz>
          <izz>4.3E-05</izz>
        </inertia>
      </inertial>
      <visual name='rotor0_visual'>
        <pose>0 0 0 0 -0 0</pose>
        <geometry>
          <mesh>
            <scale>1 1 1</scale>
            <uri>model://m4/meshes/rotor0.STL</uri>
          </mesh>
        </geometry>
      </visual>
      <gravity>1</gravity>
      <velocity_decay/>
    </link>
    <link name='rotor1'>
      <!-- <kinematic>true</kinematic> -->
      <pose relative_to='arml_to_rotor1'>0 0 0 0 -0 0</pose>
      <inertial>
        <pose>0 0 0 0 0 0</pose>
        <mass>0.021</mass>
        <inertia>
          <ixx>2.2E-05</ixx>
          <ixy>0</ixy>
          <ixz>0</ixz>
          <iyy>2.2E-05</iyy>
          <iyz>0</iyz>
          <izz>4.3E-05</izz>
        </inertia>
      </inertial>
      <visual name='rotor1_visual'>
        <pose>0 0 0 0 -0 0</pose>
        <geometry>
          <mesh>
            <scale>1 1 1</scale>
            <uri>model://m4/meshes/rotor1.STL</uri>
          </mesh>
        </geometry>
      </visual>
      <gravity>1</gravity>
      <velocity_decay/>
    </link>
    <link name='rotor2'>
      <!-- <kinematic>true</kinematic> -->
      <pose relative_to='arml_to_rotor2'>0 0 0 0 -0 0</pose>
      <inertial>
        <pose>0 0 0 0 0 0</pose>
        <mass>0.021</mass>
        <inertia>
          <ixx>2.2E-05</ixx>
          <ixy>0</ixy>
          <ixz>0</ixz>
          <iyy>2.2E-05</iyy>
          <iyz>0</iyz>
          <izz>4.3E-05</izz>
        </inertia>
      </inertial>
      <visual name='rotor2_visual'>
        <pose>0 0 0 0 -0 0</pose>
        <geometry>
          <mesh>
            <scale>1 1 1</scale>
            <uri>model://m4/meshes/rotor2.STL</uri>
          </mesh>
        </geometry>
      </visual>
      <gravity>1</gravity>
      <velocity_decay/>
    </link>
    <link name='rotor3'>
      <!-- <kinematic>true</kinematic> -->
      <pose relative_to='armr_to_rotor3'>0 0 0 0 -0 0</pose>
      <inertial>
        <pose>0 0 0 0 0 0</pose>
        <mass>0.021</mass>
        <inertia>
          <ixx>2.2E-05</ixx>
          <ixy>0</ixy>
          <ixz>0</ixz>
          <iyy>2.2E-05</iyy>
          <iyz>0</iyz>
          <izz>4.3E-05</izz>
        </inertia>
      </inertial>
      <visual name='rotor3_visual'>
        <pose>0 0 0 0 -0 0</pose>
        <geometry>
          <mesh>
            <scale>1 1 1</scale>
            <uri>model://m4/meshes/rotor3.STL</uri>
          </mesh>
        </geometry>
      </visual>
      <gravity>1</gravity>
      <velocity_decay/>
    </link>
<!-- joints -->
    <joint name='base_to_arml' type='revolute'>
      <pose relative_to='base_link'>-0.00013437 0.068076 0.094 -0.0 0 0</pose>
      <parent>base_link</parent>
      <child>arml</child>
      <axis>
        <xyz>-1 0 0</xyz>
      </axis>
    </joint>
    <joint name='base_to_armr' type='revolute'>
      <pose relative_to='base_link'>-0.00013437 -0.067924 0.094 0.0 0 0</pose>
      <parent>base_link</parent>
      <child>armr</child>
      <axis>
        <xyz>1 0 0</xyz>
      </axis>
    </joint>
    <joint name='armr_to_rotor0' type='revolute'>
      <pose relative_to='armr'>0.16491 -0.13673 0.069563 0 -0 0</pose>
      <parent>armr</parent>
      <child>rotor0</child>
      <axis>
        <xyz>0 0 1</xyz>
        <limit>
          <lower>-1e+12</lower>
          <upper>1e+12</upper>
          <effort>0</effort>
          <velocity>0</velocity>
        </limit>
        <dynamics>
          <spring_reference>0</spring_reference>
          <spring_stiffness>0</spring_stiffness>
        </dynamics>
        <use_parent_model_frame>1</use_parent_model_frame>
      </axis>
    </joint>
    <joint name='arml_to_rotor1' type='revolute'>
      <pose relative_to='arml'>-0.16509 0.13673 0.069563 0 -0 0</pose>
      <parent>arml</parent>
      <child>rotor1</child>
      <axis>
        <xyz>0 0 1</xyz>
        <limit>
          <lower>-1e+12</lower>
          <upper>1e+12</upper>
          <effort>0</effort>
          <velocity>0</velocity>
        </limit>
        <dynamics>
          <spring_reference>0</spring_reference>
          <spring_stiffness>0</spring_stiffness>
        </dynamics>
        <use_parent_model_frame>1</use_parent_model_frame>
      </axis>
    </joint>
    <joint name='arml_to_rotor2' type='revolute'>
      <pose relative_to='arml'>0.16491 0.13673 0.069563 0 -0 0</pose>
      <parent>arml</parent>
      <child>rotor2</child>
      <axis>
        <xyz>0 0 1</xyz>
        <limit>
          <lower>-1e+12</lower>
          <upper>1e+12</upper>
          <effort>0</effort>
          <velocity>0</velocity>
        </limit>
        <dynamics>
          <spring_reference>0</spring_reference>
          <spring_stiffness>0</spring_stiffness>
        </dynamics>
        <use_parent_model_frame>1</use_parent_model_frame>
      </axis>
    </joint>
    <joint name='armr_to_rotor3' type='revolute'>
      <pose relative_to='armr'>-0.16509 -0.13673 0.069563 0 -0 0</pose>
      <parent>armr</parent>
      <child>rotor3</child>
      <axis>
        <xyz>0 0 1</xyz>
        <limit>
          <lower>-1e+12</lower>
          <upper>1e+12</upper>
          <effort>0</effort>
          <velocity>0</velocity>
        </limit>
        <dynamics>
          <spring_reference>0</spring_reference>
          <spring_stiffness>0</spring_stiffness>
        </dynamics>
        <use_parent_model_frame>1</use_parent_model_frame>
      </axis>
    </joint>
<!-- imu -->
    <link name='/imu_link'>
      <pose relative_to='/imu_joint'>0 0 0 0 0 0</pose>
      <inertial>
        <pose>0 0 0 0 0 0</pose>
        <mass>0.015</mass>
        <inertia>
          <ixx>1e-05</ixx>
          <ixy>0</ixy>
          <ixz>0</ixz>
          <iyy>1e-05</iyy>
          <iyz>0</iyz>
          <izz>1e-05</izz>
        </inertia>
      </inertial>
    </link>
    <joint name='/imu_joint' type='revolute'>
      <pose relative_to='base_link'>0.0755 0 0.1299 0 0 0</pose>
      <child>/imu_link</child>
      <parent>base_link</parent>
      <axis>
        <xyz>1 0 0</xyz>
        <limit>
          <lower>0</lower>
          <upper>0</upper>
          <effort>0</effort>
          <velocity>0</velocity>
        </limit>
        <dynamics>
          <spring_reference>0</spring_reference>
          <spring_stiffness>0</spring_stiffness>
        </dynamics>
        <use_parent_model_frame>1</use_parent_model_frame>
      </axis>
    </joint>
<!-- gazebo -->
    <plugin name='rosbag' filename='libgazebo_multirotor_base_plugin.so'>
      <robotNamespace/>
      <linkName>base_link</linkName>
      <rotorVelocitySlowdownSim>10</rotorVelocitySlowdownSim>
    </plugin>
    <plugin name='front_right_motor_model' filename='libgazebo_motor_model.so'>
      <robotNamespace/>
      <jointName>armr_to_rotor0</jointName>
      <linkName>rotor0</linkName>
      <turningDirection>ccw</turningDirection>
      <timeConstantUp>0.0125</timeConstantUp>
      <timeConstantDown>0.025</timeConstantDown>
      <maxRotVelocity>1401</maxRotVelocity>
      <motorConstant>1.43e-05</motorConstant>
      <momentConstant>0.018</momentConstant>
      <commandSubTopic>/gazebo/command/motor_speed</commandSubTopic>
      <motorNumber>0</motorNumber>
      <rotorDragCoefficient>0.000175</rotorDragCoefficient>
      <rollingMomentCoefficient>1e-06</rollingMomentCoefficient>
      <motorSpeedPubTopic>/motor_speed/0</motorSpeedPubTopic>
      <rotorVelocitySlowdownSim>10</rotorVelocitySlowdownSim>
    </plugin>
    <plugin name='back_left_motor_model' filename='libgazebo_motor_model.so'>
      <robotNamespace/>
      <jointName>arml_to_rotor1</jointName>
      <linkName>rotor1</linkName>
      <turningDirection>ccw</turningDirection>
      <timeConstantUp>0.0125</timeConstantUp>
      <timeConstantDown>0.025</timeConstantDown>
      <maxRotVelocity>1401</maxRotVelocity>
      <motorConstant>1.43e-05</motorConstant>
      <momentConstant>0.018</momentConstant>
      <commandSubTopic>/gazebo/command/motor_speed</commandSubTopic>
      <motorNumber>1</motorNumber>
      <rotorDragCoefficient>0.000175</rotorDragCoefficient>
      <rollingMomentCoefficient>1e-06</rollingMomentCoefficient>
      <motorSpeedPubTopic>/motor_speed/1</motorSpeedPubTopic>
      <rotorVelocitySlowdownSim>10</rotorVelocitySlowdownSim>
    </plugin>
    <plugin name='front_left_motor_model' filename='libgazebo_motor_model.so'>
      <robotNamespace/>
      <jointName>arml_to_rotor2</jointName>
      <linkName>rotor2</linkName>
      <turningDirection>cw</turningDirection>
      <timeConstantUp>0.0125</timeConstantUp>
      <timeConstantDown>0.025</timeConstantDown>
      <maxRotVelocity>1401</maxRotVelocity>
      <motorConstant>1.43e-05</motorConstant>
      <momentConstant>0.018</momentConstant>
      <commandSubTopic>/gazebo/command/motor_speed</commandSubTopic>
      <motorNumber>2</motorNumber>
      <rotorDragCoefficient>0.000175</rotorDragCoefficient>
      <rollingMomentCoefficient>1e-06</rollingMomentCoefficient>
      <motorSpeedPubTopic>/motor_speed/2</motorSpeedPubTopic>
      <rotorVelocitySlowdownSim>10</rotorVelocitySlowdownSim>
    </plugin>
    <plugin name='back_right_motor_model' filename='libgazebo_motor_model.so'>
      <robotNamespace/>
      <jointName>armr_to_rotor3</jointName>
      <linkName>rotor3</linkName>
      <turningDirection>cw</turningDirection>
      <timeConstantUp>0.0125</timeConstantUp>
      <timeConstantDown>0.025</timeConstantDown>
      <maxRotVelocity>1401</maxRotVelocity>
      <motorConstant>1.43e-05</motorConstant>
      <momentConstant>0.018</momentConstant>
      <commandSubTopic>/gazebo/command/motor_speed</commandSubTopic>
      <motorNumber>3</motorNumber>
      <rotorDragCoefficient>0.000175</rotorDragCoefficient>
      <rollingMomentCoefficient>1e-06</rollingMomentCoefficient>
      <motorSpeedPubTopic>/motor_speed/3</motorSpeedPubTopic>
      <rotorVelocitySlowdownSim>10</rotorVelocitySlowdownSim>
    </plugin>
    <include>
      <uri>model://gps</uri>
      <pose>0 0 0 0 0 0</pose>
      <name>gps0</name>
    </include>
    <joint name='gps0_joint' type='fixed'>
      <child>gps0::link</child>
      <parent>imu_joint</parent>
    </joint>
    <plugin name='groundtruth_plugin' filename='libgazebo_groundtruth_plugin.so'>
      <robotNamespace/>
    </plugin>
    <plugin name='magnetometer_plugin' filename='libgazebo_magnetometer_plugin.so'>
      <robotNamespace/>
      <pubRate>100</pubRate>
      <noiseDensity>0.0004</noiseDensity>
      <randomWalk>6.4e-06</randomWalk>
      <biasCorrelationTime>600</biasCorrelationTime>
      <magTopic>/mag</magTopic>
    </plugin>
    <plugin name='barometer_plugin' filename='libgazebo_barometer_plugin.so'>
      <robotNamespace/>
      <pubRate>50</pubRate>
      <baroTopic>/baro</baroTopic>
      <baroDriftPaPerSec>0</baroDriftPaPerSec>
    </plugin>
    <plugin name='mavlink_interface' filename='libgazebo_mavlink_interface.so'>
      <robotNamespace/>
      <imuSubTopic>/imu</imuSubTopic>
      <magSubTopic>/mag</magSubTopic>
      <baroSubTopic>/baro</baroSubTopic>
      <mavlink_addr>INADDR_ANY</mavlink_addr>
      <mavlink_tcp_port>4560</mavlink_tcp_port>
      <mavlink_udp_port>14560</mavlink_udp_port>
      <serialEnabled>0</serialEnabled>
      <serialDevice>/dev/ttyACM0</serialDevice>
      <baudRate>921600</baudRate>
      <qgc_addr>INADDR_ANY</qgc_addr>
      <qgc_udp_port>14550</qgc_udp_port>
      <sdk_addr>INADDR_ANY</sdk_addr>
      <sdk_udp_port>14540</sdk_udp_port>
      <hil_mode>0</hil_mode>
      <hil_state_level>0</hil_state_level>
      <send_vision_estimation>0</send_vision_estimation>
      <send_odometry>1</send_odometry>
      <enable_lockstep>0</enable_lockstep>
      <use_tcp>1</use_tcp>
      <motorSpeedCommandPubTopic>/gazebo/command/motor_speed</motorSpeedCommandPubTopic>
      <control_channels>
        <channel name='rotor_1'>
          <input_index>0</input_index>
          <input_offset>0</input_offset>
          <input_scaling>1401</input_scaling>
          <zero_position_disarmed>0</zero_position_disarmed>
          <zero_position_armed>210</zero_position_armed>
          <joint_control_type>velocity</joint_control_type>
        </channel>
        <channel name='rotor_2'>
          <input_index>1</input_index>
          <input_offset>0</input_offset>
          <input_scaling>1401</input_scaling>
          <zero_position_disarmed>0</zero_position_disarmed>
          <zero_position_armed>210</zero_position_armed>
          <joint_control_type>velocity</joint_control_type>
        </channel>
        <channel name='rotor_3'>
          <input_index>2</input_index>
          <input_offset>0</input_offset>
          <input_scaling>1401</input_scaling>
          <zero_position_disarmed>0</zero_position_disarmed>
          <zero_position_armed>210</zero_position_armed>
          <joint_control_type>velocity</joint_control_type>
        </channel>
        <channel name='rotor_4'>
          <input_index>3</input_index>
          <input_offset>0</input_offset>
          <input_scaling>1401</input_scaling>
          <zero_position_disarmed>0</zero_position_disarmed>
          <zero_position_armed>210</zero_position_armed>
          <joint_control_type>velocity</joint_control_type>
        </channel>
        <channel name="tilt_motor_l">
          <input_index>4</input_index>
          <input_offset>0.0</input_offset>
          <input_scaling>1.57</input_scaling>
          <zero_position_disarmed>0</zero_position_disarmed>
          <zero_position_armed>0</zero_position_armed>
          <joint_control_type>position</joint_control_type>
          <joint_name>base_to_arml</joint_name>
           <joint_control_pid>
            <p>100</p>
            <i>0</i>
            <d>0.1</d>
            <iMax>0.0</iMax>
            <iMin>0.0</iMin>
            <cmdMax>10000000000</cmdMax>
            <cmdMin>-10000000000</cmdMin>
          </joint_control_pid>
        </channel>
        <channel name="tilt_motor_r">
          <input_index>5</input_index>
          <input_offset>0.0</input_offset>
          <input_scaling>1.57</input_scaling>
          <zero_position_disarmed>0</zero_position_disarmed>
          <zero_position_armed>0</zero_position_armed>
          <joint_control_type>position</joint_control_type>
          <joint_name>base_to_armr</joint_name>
           <joint_control_pid>
            <p>100</p>
            <i>0</i>
            <d>0.1</d>
            <iMax>0.0</iMax>
            <iMin>0.0</iMin>
            <cmdMax>10000000000</cmdMax>
            <cmdMin>-1000000000</cmdMin>
          </joint_control_pid>
        </channel>
      </control_channels>
    </plugin>
    <static>0</static>
    <plugin name='rotors_gazebo_imu_plugin' filename='libgazebo_imu_plugin.so'>
      <robotNamespace/>
      <linkName>/imu_link</linkName>
      <imuTopic>/imu</imuTopic>
      <gyroscopeNoiseDensity>0.00018665</gyroscopeNoiseDensity>
      <gyroscopeRandomWalk>3.8785e-05</gyroscopeRandomWalk>
      <gyroscopeBiasCorrelationTime>1000.0</gyroscopeBiasCorrelationTime>
      <gyroscopeTurnOnBiasSigma>0.0087</gyroscopeTurnOnBiasSigma>
      <accelerometerNoiseDensity>0.00186</accelerometerNoiseDensity>
      <accelerometerRandomWalk>0.006</accelerometerRandomWalk>
      <accelerometerBiasCorrelationTime>300.0</accelerometerBiasCorrelationTime>
      <accelerometerTurnOnBiasSigma>0.196</accelerometerTurnOnBiasSigma>
    </plugin>
  </model>
</sdf>
